Task exception was never retrieved
future: <Task finished name='Task-14' coro=<chatMan() done, defined at /home/aivan/codebox/codespaces/space/tokenbardsp/bot.py:76> exception=TimedOut('Timed out')>
Traceback (most recent call last):
  File "/home/aivan/.local/lib/python3.9/site-packages/httpcore/backends/asyncio.py", line 114, in connect_tcp
    stream: anyio.abc.ByteStream = await anyio.connect_tcp(
  File "/home/aivan/.local/lib/python3.9/site-packages/anyio/_core/_sockets.py", line 221, in connect_tcp
    await event.wait()
  File "/home/aivan/.local/lib/python3.9/site-packages/anyio/_backends/_asyncio.py", line 597, in __aexit__
    raise exceptions[0]
  File "/usr/lib/python3.9/asyncio/tasks.py", line 258, in __step
    result = coro.throw(exc)
  File "/home/aivan/.local/lib/python3.9/site-packages/anyio/_core/_sockets.py", line 167, in try_connect
    stream = await asynclib.connect_tcp(remote_host, remote_port, local_address)
  File "/home/aivan/.local/lib/python3.9/site-packages/anyio/_backends/_asyncio.py", line 1627, in connect_tcp
    await get_running_loop().create_connection(
  File "/usr/lib/python3.9/asyncio/base_events.py", line 1041, in create_connection
    sock = await self._connect_sock(
  File "/usr/lib/python3.9/asyncio/base_events.py", line 955, in _connect_sock
    await self.sock_connect(sock, address)
  File "/usr/lib/python3.9/asyncio/selector_events.py", line 502, in sock_connect
    return await fut
  File "/usr/lib/python3.9/asyncio/futures.py", line 284, in __await__
    yield self  # This tells Task to wait for completion.
  File "/usr/lib/python3.9/asyncio/tasks.py", line 328, in __wakeup
    future.result()
  File "/usr/lib/python3.9/asyncio/futures.py", line 196, in result
    raise exc
asyncio.exceptions.CancelledError

During handling of the above exception, another exception occurred:

Traceback (most recent call last):
  File "/home/aivan/.local/lib/python3.9/site-packages/httpcore/_exceptions.py", line 10, in map_exceptions
    yield
  File "/home/aivan/.local/lib/python3.9/site-packages/httpcore/backends/asyncio.py", line 121, in connect_tcp
    stream._raw_socket.setsockopt(*option)  # type: ignore[attr-defined] # pragma: no cover
  File "/home/aivan/.local/lib/python3.9/site-packages/anyio/_core/_tasks.py", line 119, in __exit__
    raise TimeoutError
TimeoutError

The above exception was the direct cause of the following exception:

Traceback (most recent call last):
  File "/home/aivan/.local/lib/python3.9/site-packages/httpx/_transports/default.py", line 60, in map_httpcore_exceptions
    yield
  File "/home/aivan/.local/lib/python3.9/site-packages/httpx/_transports/default.py", line 353, in handle_async_request
    resp = await self._pool.handle_async_request(req)
  File "/home/aivan/.local/lib/python3.9/site-packages/httpcore/_async/connection_pool.py", line 261, in handle_async_request
    raise exc
  File "/home/aivan/.local/lib/python3.9/site-packages/httpcore/_async/connection_pool.py", line 245, in handle_async_request
    response = await connection.handle_async_request(request)
  File "/home/aivan/.local/lib/python3.9/site-packages/httpcore/_async/connection.py", line 92, in handle_async_request
    raise exc
  File "/home/aivan/.local/lib/python3.9/site-packages/httpcore/_async/connection.py", line 69, in handle_async_request
    stream = await self._connect(request)
  File "/home/aivan/.local/lib/python3.9/site-packages/httpcore/_async/connection.py", line 117, in _connect
    stream = await self._network_backend.connect_tcp(**kwargs)
  File "/home/aivan/.local/lib/python3.9/site-packages/httpcore/backends/auto.py", line 31, in connect_tcp
    return await self._backend.connect_tcp(
  File "/home/aivan/.local/lib/python3.9/site-packages/httpcore/backends/asyncio.py", line 121, in connect_tcp
    stream._raw_socket.setsockopt(*option)  # type: ignore[attr-defined] # pragma: no cover
  File "/usr/lib/python3.9/contextlib.py", line 135, in __exit__
    self.gen.throw(type, value, traceback)
  File "/home/aivan/.local/lib/python3.9/site-packages/httpcore/_exceptions.py", line 14, in map_exceptions
    raise to_exc(exc) from exc
httpcore.ConnectTimeout

The above exception was the direct cause of the following exception:

Traceback (most recent call last):
  File "/home/aivan/.local/lib/python3.9/site-packages/telegram/request/_httpxrequest.py", line 216, in do_request
    res = await self._client.request(
  File "/home/aivan/.local/lib/python3.9/site-packages/httpx/_client.py", line 1530, in request
    return await self.send(request, auth=auth, follow_redirects=follow_redirects)
  File "/home/aivan/.local/lib/python3.9/site-packages/httpx/_client.py", line 1617, in send
    response = await self._send_handling_auth(
  File "/home/aivan/.local/lib/python3.9/site-packages/httpx/_client.py", line 1645, in _send_handling_auth
    response = await self._send_handling_redirects(
  File "/home/aivan/.local/lib/python3.9/site-packages/httpx/_client.py", line 1682, in _send_handling_redirects
    response = await self._send_single_request(request)
  File "/home/aivan/.local/lib/python3.9/site-packages/httpx/_client.py", line 1719, in _send_single_request
    response = await transport.handle_async_request(request)
  File "/home/aivan/.local/lib/python3.9/site-packages/httpx/_transports/default.py", line 353, in handle_async_request
    resp = await self._pool.handle_async_request(req)
  File "/usr/lib/python3.9/contextlib.py", line 135, in __exit__
    self.gen.throw(type, value, traceback)
  File "/home/aivan/.local/lib/python3.9/site-packages/httpx/_transports/default.py", line 77, in map_httpcore_exceptions
    raise mapped_exc(message) from exc
httpx.ConnectTimeout

The above exception was the direct cause of the following exception:

Traceback (most recent call last):
  File "/usr/lib/python3.9/asyncio/tasks.py", line 256, in __step
    result = coro.send(None)
  File "/home/aivan/codebox/codespaces/space/tokenbardsp/bot.py", line 79, in chatMan
    await update.message.reply_text(f'pliz {cid} wait katono')
  File "/home/aivan/.local/lib/python3.9/site-packages/telegram/_message.py", line 1074, in reply_text
    return await self.get_bot().send_message(
  File "/home/aivan/.local/lib/python3.9/site-packages/telegram/ext/_extbot.py", line 2633, in send_message
    return await super().send_message(
  File "/home/aivan/.local/lib/python3.9/site-packages/telegram/_bot.py", line 381, in decorator
    result = await func(self, *args, **kwargs)  # skipcq: PYL-E1102
  File "/home/aivan/.local/lib/python3.9/site-packages/telegram/_bot.py", line 807, in send_message
    return await self._send_message(
  File "/home/aivan/.local/lib/python3.9/site-packages/telegram/ext/_extbot.py", line 507, in _send_message
    result = await super()._send_message(
  File "/home/aivan/.local/lib/python3.9/site-packages/telegram/_bot.py", line 559, in _send_message
    result = await self._post(
  File "/home/aivan/.local/lib/python3.9/site-packages/telegram/_bot.py", line 469, in _post
    return await self._do_post(
  File "/home/aivan/.local/lib/python3.9/site-packages/telegram/ext/_extbot.py", line 325, in _do_post
    return await super()._do_post(
  File "/home/aivan/.local/lib/python3.9/site-packages/telegram/_bot.py", line 497, in _do_post
    return await request.post(
  File "/home/aivan/.local/lib/python3.9/site-packages/telegram/request/_baserequest.py", line 168, in post
    result = await self._request_wrapper(
  File "/home/aivan/.local/lib/python3.9/site-packages/telegram/request/_baserequest.py", line 291, in _request_wrapper
    raise exc
  File "/home/aivan/.local/lib/python3.9/site-packages/telegram/request/_baserequest.py", line 277, in _request_wrapper
    code, payload = await self.do_request(
  File "/home/aivan/.local/lib/python3.9/site-packages/telegram/request/_httpxrequest.py", line 233, in do_request
    raise TimedOut from err
telegram.error.TimedOut: Timed out
